{"type": "error", "data": "Community Report Extraction Error", "stack": "Traceback (most recent call last):\n  File \"/home/user16/baltsat/graphrag-local-ollama/graphrag/index/graph/extractors/community_reports/community_reports_extractor.py\", line 58, in __call__\n    await self._llm(\n  File \"/home/user16/baltsat/graphrag-local-ollama/graphrag/llm/openai/json_parsing_llm.py\", line 34, in __call__\n    result = await self._delegate(input, **kwargs)\n  File \"/home/user16/baltsat/graphrag-local-ollama/graphrag/llm/openai/openai_token_replacing_llm.py\", line 37, in __call__\n    return await self._delegate(input, **kwargs)\n  File \"/home/user16/baltsat/graphrag-local-ollama/graphrag/llm/openai/openai_history_tracking_llm.py\", line 33, in __call__\n    output = await self._delegate(input, **kwargs)\n  File \"/home/user16/baltsat/graphrag-local-ollama/graphrag/llm/base/caching_llm.py\", line 104, in __call__\n    result = await self._delegate(input, **kwargs)\n  File \"/home/user16/baltsat/graphrag-local-ollama/graphrag/llm/base/rate_limiting_llm.py\", line 177, in __call__\n    result, start = await execute_with_retry()\n  File \"/home/user16/baltsat/graphrag-local-ollama/graphrag/llm/base/rate_limiting_llm.py\", line 159, in execute_with_retry\n    async for attempt in retryer:\n  File \"/home/user16/miniconda3/envs/baltsat-graphrag/lib/python3.10/site-packages/tenacity/asyncio/__init__.py\", line 166, in __anext__\n    do = await self.iter(retry_state=self._retry_state)\n  File \"/home/user16/miniconda3/envs/baltsat-graphrag/lib/python3.10/site-packages/tenacity/asyncio/__init__.py\", line 153, in iter\n    result = await action(retry_state)\n  File \"/home/user16/miniconda3/envs/baltsat-graphrag/lib/python3.10/site-packages/tenacity/_utils.py\", line 99, in inner\n    return call(*args, **kwargs)\n  File \"/home/user16/miniconda3/envs/baltsat-graphrag/lib/python3.10/site-packages/tenacity/__init__.py\", line 398, in <lambda>\n    self._add_action_func(lambda rs: rs.outcome.result())\n  File \"/home/user16/miniconda3/envs/baltsat-graphrag/lib/python3.10/concurrent/futures/_base.py\", line 451, in result\n    return self.__get_result()\n  File \"/home/user16/miniconda3/envs/baltsat-graphrag/lib/python3.10/concurrent/futures/_base.py\", line 403, in __get_result\n    raise self._exception\n  File \"/home/user16/baltsat/graphrag-local-ollama/graphrag/llm/base/rate_limiting_llm.py\", line 165, in execute_with_retry\n    return await do_attempt(), start\n  File \"/home/user16/baltsat/graphrag-local-ollama/graphrag/llm/base/rate_limiting_llm.py\", line 147, in do_attempt\n    return await self._delegate(input, **kwargs)\n  File \"/home/user16/baltsat/graphrag-local-ollama/graphrag/llm/base/base_llm.py\", line 48, in __call__\n    return await self._invoke_json(input, **kwargs)\n  File \"/home/user16/baltsat/graphrag-local-ollama/graphrag/llm/openai/openai_chat_llm.py\", line 90, in _invoke_json\n    raise RuntimeError(FAILED_TO_CREATE_JSON_ERROR)\nRuntimeError: Failed to generate valid JSON output\n", "source": "Failed to generate valid JSON output", "details": null}
